Workbook
Name Slicer_Category: #N/A
Name Slicer_CustomerType: #N/A
Name Slicer_OrderDate: #N/A
Name Slicer_Region: #N/A
Name Slicer_Salesperson: #N/A

Sheet SalesData
A1: OrderID | B1: OrderDate | C1: Region | D1: Category | E1: Product | F1: Salesperson | G1: Quantity | H1: UnitPrice | I1: Sales | J1: TargetSales | K1: CustomerType | L1: Achievement Target
A2: 1001 | B2: 45888 | C2: South | D2: Electronics | E2: Laptop | F2: Sara | G2: 9 | H2: 176 | I2: 1584 | J2: 1951 | K2: Wholesale | L2: =SalesData!I2/SalesData!J2 -> 0.81189134
A3: 1002 | B3: 45980 | C3: East | D3: Furniture | E3: Desk | F3: Usman | G3: 9 | H3: 405 | I3: 3645 | J3: 3523 | K3: Retail | L3: =SalesData!I3/SalesData!J3 -> 1.0346296
A4: 1003 | B4: 45670 | C4: South | D4: Electronics | E4: Monitor | F4: Ahmed | G4: 2 | H4: 152 | I4: 304 | J4: 373 | K4: Retail | L4: =SalesData!I4/SalesData!J4 -> 0.8150134
A5: 1004 | B5: 45916 | C5: South | D5: Office Supplies | E5: Stapler | F5: Sara | G5: 10 | H5: 494 | I5: 4940 | J5: 5312 | K5: Wholesale | L5: =SalesData!I5/SalesData!J5 -> 0.92996988
A6: 1005 | B6: 45778 | C6: North | D6: Office Supplies | E6: Paper | F6: Usman | G6: 9 | H6: 178 | I6: 1602 | J6: 1745 | K6: Wholesale | L6: =SalesData!I6/SalesData!J6 -> 0.91805158
A7: 1006 | B7: 45761 | C7: North | D7: Furniture | E7: Chair | F7: Usman | G7: 4 | H7: 298 | I7: 1192 | J7: 1418 | K7: Retail | L7: =SalesData!I7/SalesData!J7 -> 0.84062059
A8: 1007 | B8: 45702 | C8: West | D8: Electronics | E8: Monitor | F8: Ali | G8: 4 | H8: 338 | I8: 1352 | J8: 1207 | K8: Wholesale | L8: =SalesData!I8/SalesData!J8 -> 1.1201326
A9: 1008 | B9: 45862 | C9: South | D9: Furniture | E9: Cabinet | F9: Ayesha | G9: 7 | H9: 377 | I9: 2639 | J9: 2874 | K9: Wholesale | L9: =SalesData!I9/SalesData!J9 -> 0.91823243
A10: 1009 | B10: 45791 | C10: South | D10: Electronics | E10: Monitor | F10: Fatima | G10: 7 | H10: 466 | I10: 3262 | J10: 4014 | K10: Retail | L10: =SalesData!I10/SalesData!J10 -> 0.81265571
A11: 1010 | B11: 45921 | C11: South | D11: Furniture | E11: Chair | F11: Fatima | G11: 1 | H11: 469 | I11: 469 | J11: 516 | K11: Retail | L11: =SalesData!I11/SalesData!J11 -> 0.90891473
A12: 1011 | B12: 45836 | C12: West | D12: Electronics | E12: Monitor | F12: Usman | G12: 4 | H12: 250 | I12: 1000 | J12: 1115 | K12: Wholesale | L12: =SalesData!I12/SalesData!J12 -> 0.89686099
A13: 1012 | B13: 45921 | C13: North | D13: Electronics | E13: Monitor | F13: Sara | G13: 1 | H13: 317 | I13: 317 | J13: 265 | K13: Wholesale | L13: =SalesData!I13/SalesData!J13 -> 1.1962264
... A501: 1500 | B501: 45914 | C501: West | D501: Office Supplies | E501: Paper | F501: Fatima | G501: 4 | H501: 183 | I501: 732 | J501: 833 | K501: Retail | L501: =SalesData!I501/SalesData!J501 -> 0.8787515

Sheet Problems
A1: Excel KPI Reporting Practice Questions | B1: Below is a professional KPI dashboard layout that you can use as a reference while building your own Excel dashboard.
A3: Create a professional KPI Dashboard that answers the following business questions. | B3: Sample Excel KPI Dashboard
A5: KPI Cards | B5: +--------------------------------------------------------------------------------------+
B6: | SALES KPI DASHBOARD - 2025 |
A7: 1. Total Sales | B7: +--------------------------------------------------------------------------------------+
A9: 2. Total Orders | B9: ┌─────────────┐ ┌─────────────┐ ┌─────────────┐ ┌─────────────┐ ┌─────────────┐
B10: | Total Sales | | Total Orders| | Total Qty | | Avg Order | | Achievement |
A11: 3. Total Quantity Sold | B11: | $1,245,890 | | 5,420 | | 18,350 | | $230 | | 97.8% |
B12: └─────────────┘ └─────────────┘ └─────────────┘ └─────────────┘ └─────────────┘
A13: 4. Average Order Value
B14: Slicers:
A15: 5. Total Target Sales | B15: [ Year ] [ Month ] [ Region ] [ Category ] [ Salesperson ] [ Customer Type ]
A17: 6. Sales Achievement % | B17: ----------------------------------------------------------------------------------------
B19: Monthly Sales Trend Sales vs Target
A21: Formula: | B21: (Line Chart) (Clustered Column Chart)
A22: Total Sales / Total Target Sales
B23: Jan ███ Target ████
A24: 7. Best Performing Region | B24: Feb █████ Actual ███
B25: Mar ██████
A26: 8. Best Performing Category | B26: Apr ███████
A28: 9. Best Selling Product | B28: ----------------------------------------------------------------------------------------
A30: 10. Best Salesperson | B30: Sales by Region Sales by Category
B32: (Bar Chart) (Donut Chart)
A34: Trend Analysis | B34: North █████████ Electronics 45%
B35: South ███████ Furniture 30%
A36: Create charts for: | B36: East █████ Office 25%
B37: West ███████
A38: Monthly Sales Trend
B39: ----------------------------------------------------------------------------------------
A40: Monthly Target vs Actual Sales
B41: Top 10 Products Top Salespersons
A42: Quarterly Sales Trend
B43: (Bar Chart) (Horizontal Bar)
A44: Monthly Quantity Sold
B45: Laptop ██████████ Ali █████████
B46: Monitor ███████ Sara ███████
B47: Keyboard █████ Ahmed ██████
A48: Region Analysis
B49: ----------------------------------------------------------------------------------------
A50: Create:
...

Sheet Sheet2
J1: Best Category | M1: Best Region
J2: Row Labels | K2: Sum of Sales | M2: Row Labels | N2: Sum of Sales
J3: Furniture | K3: 265646 | M3: North | N3: 200498
J4: Office Supplies | K4: 258857 | M4: East | N4: 184987
J5: Electronics | K5: 216639 | M5: West | N5: 179018
J6: Grand Total | K6: 741142 | M6: South | N6: 176639
A7: Row Labels | B7: Sum of Sales | C7: Sum of Quantity | D7: Sum of TargetSales | E7: Sum of Achievement Target | M7: Grand Total | N7: 741142
A8: 1001 | B8: 1584 | C8: 9 | D8: 1951 | E8: 0.81189134 | G8: KPI Cards | J8: Best Product | M8: Best Sale Person
A9: 1002 | B9: 3645 | C9: 9 | D9: 3523 | E9: 1.0346296 | J9: Row Labels | K9: Sum of Sales | M9: Row Labels | N9: Sum of Sales
A10: 1003 | B10: 304 | C10: 2 | D10: 373 | E10: 0.8150134 | G10: 1. Total Sales | H10: =B508 -> 741142 | J10: Cabinet | K10: 97579 | M10: Sara | N10: 139218
A11: 1004 | B11: 4940 | C11: 10 | D11: 5312 | E11: 0.92996988 | J11: Stapler | K11: 94695 | M11: Fatima | N11: 131739
A12: 1005 | B12: 1602 | C12: 9 | D12: 1745 | E12: 0.91805158 | G12: 2. Total Orders | H12: =A508 -> 500 | J12: Chair | K12: 85125 | M12: Ali | N12: 124002
A13: 1006 | B13: 1192 | C13: 4 | D13: 1418 | E13: 0.84062059 | J13: Pen | K13: 83864 | M13: Ayesha | N13: 123689
A14: 1007 | B14: 1352 | C14: 4 | D14: 1207 | E14: 1.1201326 | G14: 3. Total Quantity Sold | H14: =C508 -> 2797 | J14: Desk | K14: 82942 | M14: Usman | N14: 117984
A15: 1008 | B15: 2639 | C15: 7 | D15: 2874 | E15: 0.91823243 | J15: Paper | K15: 80298 | M15: Ahmed | N15: 104510
A16: 1009 | B16: 3262 | C16: 7 | D16: 4014 | E16: 0.81265571 | G16: 4. Average Order Value | H16: =H10/H12 -> 1482.284 | J16: Mouse | K16: 58814 | M16: Grand Total | N16: 741142
A17: 1010 | B17: 469 | C17: 1 | D17: 516 | E17: 0.90891473 | J17: Keyboard | K17: 56455
A18: 1011 | B18: 1000 | C18: 4 | D18: 1115 | E18: 0.89686099 | G18: 5. Total Target Sales | H18: =D508 -> 778118 | J18: Laptop | K18: 55934
A19: 1012 | B19: 317 | C19: 1 | D19: 265 | E19: 1.1962264 | J19: Monitor | K19: 45436
A20: 1013 | B20: 2350 | C20: 10 | D20: 2188 | E20: 1.0740402 | G20: 6. Sales Achievement % | H20: =E508 -> 484.56253 | J20: Grand Total | K20: 741142
A21: 1014 | B21: 2400 | C21: 6 | D21: 2323 | E21: 1.0331468
A22: 1015 | B22: 464 | C22: 1 | D22: 522 | E22: 0.88888889 | J22: Monthly Sale Trend | M22: Monthly Target vs Actual Sales
A23: 1016 | B23: 948 | C23: 6 | D23: 977 | E23: 0.9703173 | J23: Row Labels | K23: Sum of Sales | M23: Row Labels | N23: Sum of TargetSales | O23: Sum of Sales
A24: 1017 | B24: 2290 | C24: 10 | D24: 2166 | E24: 1.0572484 | G24: Formula: | J24: 2025 | M24: 2025
A25: 1018 | B25: 324 | C25: 4 | D25: 377 | E25: 0.85941645 | G25: Total Sales / Total Target Sales | J25: Jan | K25: 81318 | M25: Jan | N25: 87431 | O25: 81318
A26: 1019 | B26: 396 | C26: 3 | D26: 448 | E26: 0.88392857 | J26: Feb | K26: 56266 | M26: Feb | N26: 58810 | O26: 56266
A27: 1020 | B27: 132 | C27: 3 | D27: 151 | E27: 0.87417219 | G27: 7. Best Performing Region | H27: =M3 -> North | J27: Mar | K27: 62195 | M27: Mar | N27: 65130 | O27: 62195
A28: 1021 | B28: 247 | C28: 1 | D28: 301 | E28: 0.82059801 | J28: Apr | K28: 42440 | M28: Apr | N28: 45214 | O28: 42440
A29: 1022 | B29: 2415 | C29: 5 | D29: 2528 | E29: 0.95530063 | G29: 8. Best Performing Category | H29: =J3 -> Furniture | J29: May | K29: 57361 | M29: May | N29: 60072 | O29: 57361
A30: 1023 | B30: 666 | C30: 9 | D30: 547 | E30: 1.2175503 | J30: Jun | K30: 57984 | M30: Jun | N30: 59156 | O30: 57984
A31: 1024 | B31: 1179 | C31: 9 | D31: 1305 | E31: 0.90344828 | G31: 9. Best Selling Product | H31: =J10 -> Cabinet | J31: Jul | K31: 57873 | M31: Jul | N31: 59838 | O31: 57873
A32: 1025 | B32: 3479 | C32: 7 | D32: 4502 | E32: 0.77276766 | J32: Aug | K32: 76696 | M32: Aug | N32: 83232 | O32: 76696
A33: 1026 | B33: 4041 | C33: 9 | D33: 4013 | E33: 1.0069773 | G33: 10. Best Salesperson | J33: Sep | K33: 76886 | M33: Sep | N33: 82888 | O33: 76886
A34: 1027 | B34: 1505 | C34: 5 | D34: 1420 | E34: 1.0598592 | J34: Oct | K34: 55092 | M34: Oct | N34: 57929 | O34: 55092
A35: 1028 | B35: 4212 | C35: 9 | D35: 3436 | E35: 1.225844 | J35: Nov | K35: 58775 | M35: Nov | N35: 57992 | O35: 58775
A36: 1029 | B36: 202 | C36: 2 | D36: 237 | E36: 0.85232068 | J36: Dec | K36: 58256 | M36: Dec | N36: 60426 | O36: 58256
A37: 1030 | B37: 2502 | C37: 6 | D37: 2759 | E37: 0.90685031 | G37: Trend Analysis | J37: Grand Total | K37: 741142 | M37: Grand Total | N37: 778118 | O37: 741142
A38: 1031 | B38: 2457 | C38: 7 | D38: 2004 | E38: 1.2260479
A39: 1032 | B39: 2850 | C39: 6 | D39: 2432 | E39: 1.171875 | G39: Create charts for: | J39: Quarterly Sale
A40: 1033 | B40: 2954 | C40: 7 | D40: 2466 | E40: 1.1978913 | J40: Row Labels | K40: Sum of Sales | M40: Monthly Quantity Sold
...

Sheet Deshboard
A1: Sale KPI Deshboard 2025
